Workbook

Sheet Masterfile
A1: RTM | B1: PUB | C1: STREET | D1: VILLAGE | E1: TOWN | F1: COUNTY | G1: POSTCODE | H1: POST DISTRICT | I1: POST SECTOR | J1: RM | K1: STRATEGY | L1: Notes
A2: Greene King L&T | B2: Horse & Groom | C2: 20 Rayne Road | D2: Braintree | F2: Essex | G2: CM7 2QA | H2: =_xlfn.TEXTBEFORE(G2," ") -> CM7 | I2: {=LEFT(G2, MIN(IF(ISNUMBER(--MID(G2, _xlfn.SEQUENCE(LEN(G2)), 1)), _xlfn.SEQUENCE(LEN(G2)))) - 1)} -> CM | J2: James Pearson | K2: GROW - Stella/SM +1 | L2: Won San Miguel here a few months ago. Veronica running pub after her husband passed away but her duaghter Antionette really makes the decisions. Should be able to get more stuff here but is Tier 3
A3: Greene King IFT | B3: Tomos Tavern Limited | G3: CM7 2TH | H3: =_xlfn.TEXTBEFORE(G3," ") -> CM7 | I3: {=LEFT(G3, MIN(IF(ISNUMBER(--MID(G3, _xlfn.SEQUENCE(LEN(G3)), 1)), _xlfn.SEQUENCE(LEN(G3)))) - 1)} -> CM | J3: =_xlfn.XLOOKUP(H3,'GK IFT SDM POSTCODES'!A:A,'GK IFT SDM POSTCODES'!B:B,"") -> Nikki Hayter | K3: GET
A4: Greene King IFT | B4: Loft Tavern (Braintree) | G4: CM7 2TH | H4: =_xlfn.TEXTBEFORE(G4," ") -> CM7 | I4: {=LEFT(G4, MIN(IF(ISNUMBER(--MID(G4, _xlfn.SEQUENCE(LEN(G4)), 1)), _xlfn.SEQUENCE(LEN(G4)))) - 1)} -> CM | J4: =_xlfn.XLOOKUP(H4,'GK IFT SDM POSTCODES'!A:A,'GK IFT SDM POSTCODES'!B:B,"") -> Nikki Hayter | K4: GET
A5: Admiral | B5: Nags Head Wine Bar, Braintree | C5: 8 Market Place, | E5: Braintree | G5: CM7 3HG | H5: =_xlfn.TEXTBEFORE(G5," ") -> CM7 | I5: {=LEFT(G5, MIN(IF(ISNUMBER(--MID(G5, _xlfn.SEQUENCE(LEN(G5)), 1)), _xlfn.SEQUENCE(LEN(G5)))) - 1)} -> CM | J5: Nicky Bellingham | K5: GROW - Stella/SM +1 | L5: Proper Pubs. Stella on and good to support
A6: Greene King IFT | B6: Sportsman (Braintree) | G6: CM7 3QX | H6: =_xlfn.TEXTBEFORE(G6," ") -> CM7 | I6: {=LEFT(G6, MIN(IF(ISNUMBER(--MID(G6, _xlfn.SEQUENCE(LEN(G6)), 1)), _xlfn.SEQUENCE(LEN(G6)))) - 1)} -> CM | J6: =_xlfn.XLOOKUP(H6,'GK IFT SDM POSTCODES'!A:A,'GK IFT SDM POSTCODES'!B:B,"") -> Nikki Hayter | K6: GROW - Stella/SM +1 | L6: Small place with Stella on bar. Not much opps other than San Mig
A7: Greene King IFT | B7: Horse & Groom PH (Cornish Hall End) | G7: CM7 4HF | H7: =_xlfn.TEXTBEFORE(G7," ") -> CM7 | I7: {=LEFT(G7, MIN(IF(ISNUMBER(--MID(G7, _xlfn.SEQUENCE(LEN(G7)), 1)), _xlfn.SEQUENCE(LEN(G7)))) - 1)} -> CM | J7: =_xlfn.XLOOKUP(H7,'GK IFT SDM POSTCODES'!A:A,'GK IFT SDM POSTCODES'!B:B,"") -> Nikki Hayter | K7: GET
A8: Greene King IFT | B8: Vine (Great Bardfield) | G8: CM7 4SR | H8: =_xlfn.TEXTBEFORE(G8," ") -> CM7 | I8: {=LEFT(G8, MIN(IF(ISNUMBER(--MID(G8, _xlfn.SEQUENCE(LEN(G8)), 1)), _xlfn.SEQUENCE(LEN(G8)))) - 1)} -> CM | J8: =_xlfn.XLOOKUP(H8,'GK IFT SDM POSTCODES'!A:A,'GK IFT SDM POSTCODES'!B:B,"") -> Nikki Hayter | K8: GET | L8: good opps here for stella, More premium beers and lots fo POS around but could never get LL contact
A9: Greene King L&T | B9: Bell | C9: Kynaston Road | D9: Panfield | E9: Braintree | F9: Essex | G9: CM7 5AQ | H9: =_xlfn.TEXTBEFORE(G9," ") -> CM7 | I9: {=LEFT(G9, MIN(IF(ISNUMBER(--MID(G9, _xlfn.SEQUENCE(LEN(G9)), 1)), _xlfn.SEQUENCE(LEN(G9)))) - 1)} -> CM | J9: James Pearson | K9: GROW | L9: Went here with TNT a few times and was THIS close to a deal. Would never take Stella. Wanted Corona but JP dragged his feet on it. Right next to a football pitch so can do an outside bar. Family run pub but Dad and Son make decisions (cant remmeber names lol)
A10: Greene King IFT | B10: Bocking United Serv Social Club | G10: CM7 5LA | H10: =_xlfn.TEXTBEFORE(G10," ") -> CM7 | I10: {=LEFT(G10, MIN(IF(ISNUMBER(--MID(G10, _xlfn.SEQUENCE(LEN(G10)), 1)), _xlfn.SEQUENCE(LEN(G10)))) - 1)} -> CM | J10: =_xlfn.XLOOKUP(H10,'GK IFT SDM POSTCODES'!A:A,'GK IFT SDM POSTCODES'!B:B,"") -> Nikki Hayter | K10: GET | L10: HUK Smart Dispense so tricky one
A11: Greene King IFT | B11: Bocking Social Club Limited | G11: CM7 5LA | H11: =_xlfn.TEXTBEFORE(G11," ") -> CM7 | I11: {=LEFT(G11, MIN(IF(ISNUMBER(--MID(G11, _xlfn.SEQUENCE(LEN(G11)), 1)), _xlfn.SEQUENCE(LEN(G11)))) - 1)} -> CM | J11: =_xlfn.XLOOKUP(H11,'GK IFT SDM POSTCODES'!A:A,'GK IFT SDM POSTCODES'!B:B,"") -> Nikki Hayter | K11: GET | L11: HUK Smart Dispense so tricky one
A12: Greene King IFT | B12: O'Gradys (Braintree) | G12: CM7 5RL | H12: =_xlfn.TEXTBEFORE(G12," ") -> CM7 | I12: {=LEFT(G12, MIN(IF(ISNUMBER(--MID(G12, _xlfn.SEQUENCE(LEN(G12)), 1)), _xlfn.SEQUENCE(LEN(G12)))) - 1)} -> CM | J12: =_xlfn.XLOOKUP(H12,'GK IFT SDM POSTCODES'!A:A,'GK IFT SDM POSTCODES'!B:B,"") -> Nikki Hayter | K12: KEEP | L12: Don't bother
A13: Admiral | B13: Eagle, Braintree | C13: 192 Coggeshall Road, | E13: Braintree | G13: CM7 9ER | H13: =_xlfn.TEXTBEFORE(G13," ") -> CM7 | I13: {=LEFT(G13, MIN(IF(ISNUMBER(--MID(G13, _xlfn.SEQUENCE(LEN(G13)), 1)), _xlfn.SEQUENCE(LEN(G13)))) - 1)} -> CM | J13: Nicky Bellingham | K13: GROW - Stella/SM +1 | L13: Proper Pubs. Stella on and good to support
A14: Greene King IFT | B14: Swiss Bell (Braintree) | G14: CM7 9UL | H14: =_xlfn.TEXTBEFORE(G14," ") -> CM7 | I14: {=LEFT(G14, MIN(IF(ISNUMBER(--MID(G14, _xlfn.SEQUENCE(LEN(G14)), 1)), _xlfn.SEQUENCE(LEN(G14)))) - 1)} -> CM | J14: =_xlfn.XLOOKUP(H14,'GK IFT SDM POSTCODES'!A:A,'GK IFT SDM POSTCODES'!B:B,"") -> Nikki Hayter | K14: GET
A15: Admiral | B15: Welsh Princess, Rayne | C15: 21 The Street, Braintree | E15: Rayne | G15: CM77 6RW | H15: =_xlfn.TEXTBEFORE(G15," ") -> CM77 | I15: {=LEFT(G15, MIN(IF(ISNUMBER(--MID(G15, _xlfn.SEQUENCE(LEN(G15)), 1)), _xlfn.SEQUENCE(LEN(G15)))) - 1)} -> CM | J15: James McIver | K15: GET | L15: Was closed for most of my time with it but may be reopen
A16: Greene King IFT | B16: Braintree Golf Club (Braintree) | G16: CM77 8DD | H16: =_xlfn.TEXTBEFORE(G16," ") -> CM77 | I16: {=LEFT(G16, MIN(IF(ISNUMBER(--MID(G16, _xlfn.SEQUENCE(LEN(G16)), 1)), _xlfn.SEQUENCE(LEN(G16)))) - 1)} -> CM | J16: =_xlfn.XLOOKUP(H16,'GK IFT SDM POSTCODES'!A:A,'GK IFT SDM POSTCODES'!B:B,"") -> Nikki Hayter | K16: GET | L16: CMBC direct. Buys ales through GK so Neil Stebbing will wnt to increase distro. San Mig was on before they took it off
A17: Greene King IFT | B17: Black Notley Community Association | G17: CM77 8NE | H17: =_xlfn.TEXTBEFORE(G17," ") -> CM77 | I17: {=LEFT(G17, MIN(IF(ISNUMBER(--MID(G17, _xlfn.SEQUENCE(LEN(G17)), 1)), _xlfn.SEQUENCE(LEN(G17)))) - 1)} -> CM | J17: =_xlfn.XLOOKUP(H17,'GK IFT SDM POSTCODES'!A:A,'GK IFT SDM POSTCODES'!B:B,"") -> Nikki Hayter | K17: GROW - Stella/SM +1
A18: Greene King IFT | B18: Swan (Witham) | G18: CM8 1BE | H18: =_xlfn.TEXTBEFORE(G18," ") -> CM8 | I18: {=LEFT(G18, MIN(IF(ISNUMBER(--MID(G18, _xlfn.SEQUENCE(LEN(G18)), 1)), _xlfn.SEQUENCE(LEN(G18)))) - 1)} -> CM | J18: =_xlfn.XLOOKUP(H18,'GK IFT SDM POSTCODES'!A:A,'GK IFT SDM POSTCODES'!B:B,"") -> Neil Stebbings | K18: GROW - Stella/SM +1 | L18: good opps for San Mig but LL never in
A19: Greene King IFT | B19: RAFA Witham & Rivenhall Club | G19: CM8 1BX | H19: =_xlfn.TEXTBEFORE(G19," ") -> CM8 | I19: {=LEFT(G19, MIN(IF(ISNUMBER(--MID(G19, _xlfn.SEQUENCE(LEN(G19)), 1)), _xlfn.SEQUENCE(LEN(G19)))) - 1)} -> CM | J19: =_xlfn.XLOOKUP(H19,'GK IFT SDM POSTCODES'!A:A,'GK IFT SDM POSTCODES'!B:B,"") -> Neil Stebbings | K19: GROW - Stella/SM +1 | L19: Good opps for San Mig. Stella on and does well but small vols
A20: Greene King IFT | B20: White Notley FC (Faulkebourne) | G20: CM8 1SF | H20: =_xlfn.TEXTBEFORE(G20," ") -> CM8 | I20: {=LEFT(G20, MIN(IF(ISNUMBER(--MID(G20, _xlfn.SEQUENCE(LEN(G20)), 1)), _xlfn.SEQUENCE(LEN(G20)))) - 1)} -> CM | J20: =_xlfn.XLOOKUP(H20,'GK IFT SDM POSTCODES'!A:A,'GK IFT SDM POSTCODES'!B:B,"") -> Neil Stebbings | K20: GET
A21: Greene King L&T | B21: White Hart | C21: Newland Street | D21: Witham | F21: Essex | G21: CM8 2AF | H21: =_xlfn.TEXTBEFORE(G21," ") -> CM8 | I21: {=LEFT(G21, MIN(IF(ISNUMBER(--MID(G21, _xlfn.SEQUENCE(LEN(G21)), 1)), _xlfn.SEQUENCE(LEN(G21)))) - 1)} -> CM | J21: James Pearson | K21: GROW - Stella/SM +1
A22: Admiral | B22: George, Witham | C22: 36 Newland Street, | E22: Witham | G22: CM8 2AQ | H22: =_xlfn.TEXTBEFORE(G22," ") -> CM8 | I22: {=LEFT(G22, MIN(IF(ISNUMBER(--MID(G22, _xlfn.SEQUENCE(LEN(G22)), 1)), _xlfn.SEQUENCE(LEN(G22)))) - 1)} -> CM | J22: Troy Bett | K22: GROW - Stella/SM +1 | L22: Recently reopened and have installed Stella (already claimed W sorry)
A23: Greene King IFT | B23: Spring Lodge Community Centre | G23: CM8 2HE | H23: =_xlfn.TEXTBEFORE(G23," ") -> CM8 | I23: {=LEFT(G23, MIN(IF(ISNUMBER(--MID(G23, _xlfn.SEQUENCE(LEN(G23)), 1)), _xlfn.SEQUENCE(LEN(G23)))) - 1)} -> CM | J23: =_xlfn.XLOOKUP(H23,'GK IFT SDM POSTCODES'!A:A,'GK IFT SDM POSTCODES'!B:B,"") -> Neil Stebbings | K23: GET | L23: Laura bar personl. Good opps for Stella andSan Mig but they are reluctant to change
A24: Admiral | B24: White Horse, Witham | C24: 2 Church Street, | E24: Witham | G24: CM8 2JL | H24: =_xlfn.TEXTBEFORE(G24," ") -> CM8 | I24: {=LEFT(G24, MIN(IF(ISNUMBER(--MID(G24, _xlfn.SEQUENCE(LEN(G24)), 1)), _xlfn.SEQUENCE(LEN(G24)))) - 1)} -> CM | J24: Troy Bett | K24: GROW - Stella/SM +1 | L24: Part of MO that has two on my patch. Pale in all of them. We've got good opps to do Mahou, Stella in all three so lets team up on this
A25: Greene King IFT | B25: Woolpack Inn (Witham) | G25: CM8 2JP | H25: =_xlfn.TEXTBEFORE(G25," ") -> CM8 | I25: {=LEFT(G25, MIN(IF(ISNUMBER(--MID(G25, _xlfn.SEQUENCE(LEN(G25)), 1)), _xlfn.SEQUENCE(LEN(G25)))) - 1)} -> CM | J25: =_xlfn.XLOOKUP(H25,'GK IFT SDM POSTCODES'!A:A,'GK IFT SDM POSTCODES'!B:B,"") -> Neil Stebbings | K25: GROW - Stella/SM +1 | L25: This guy is a prick. But got him to agree San Mig IPO Fosters in principal so this is mine. Sorry not sorry
A26: Greene King IFT | B26: Little Elms (Witham) | G26: CM8 2LX | H26: =_xlfn.TEXTBEFORE(G26," ") -> CM8 | I26: {=LEFT(G26, MIN(IF(ISNUMBER(--MID(G26, _xlfn.SEQUENCE(LEN(G26)), 1)), _xlfn.SEQUENCE(LEN(G26)))) - 1)} -> CM | J26: =_xlfn.XLOOKUP(H26,'GK IFT SDM POSTCODES'!A:A,'GK IFT SDM POSTCODES'!B:B,"") -> Neil Stebbings | K26: KEEP | L26: Worst pub I've ever been to. Take a stab vest. LL never in
A27: Greene King IFT | B27: Crittall Athletic & Social Club (Si | G27: CM8 3RQ | H27: =_xlfn.TEXTBEFORE(G27," ") -> CM8 | I27: {=LEFT(G27, MIN(IF(ISNUMBER(--MID(G27, _xlfn.SEQUENCE(LEN(G27)), 1)), _xlfn.SEQUENCE(LEN(G27)))) - 1)} -> CM | J27: =_xlfn.XLOOKUP(H27,'GK IFT SDM POSTCODES'!A:A,'GK IFT SDM POSTCODES'!B:B,"") -> Neil Stebbings | K27: GET | L27: Bud Light and Stella on here. Do pretty well but I would visit just to keep close
A28: Greene King L&T | B28: Western Arms | C28: Western Road | D28: Silver End | E28: Witham | F28: Essex | G28: CM8 3SD | H28: =_xlfn.TEXTBEFORE(G28," ") -> CM8 | I28: {=LEFT(G28, MIN(IF(ISNUMBER(--MID(G28, _xlfn.SEQUENCE(LEN(G28)), 1)), _xlfn.SEQUENCE(LEN(G28)))) - 1)} -> CM | J28: James Pearson | K28: GROW | L28: Jamie is LL and also has Rose Inn on my patch. Wsnts to turn this place into an american smokehouse but doesn’t want Bud or Bud Light? JP keen for us here to pick up with him
A29: Greene King IFT | B29: Stepfield Snooker Club (Witham) | G29: CM8 3TH | H29: =_xlfn.TEXTBEFORE(G29," ") -> CM8 | I29: {=LEFT(G29, MIN(IF(ISNUMBER(--MID(G29, _xlfn.SEQUENCE(LEN(G29)), 1)), _xlfn.SEQUENCE(LEN(G29)))) - 1)} -> CM | J29: =_xlfn.XLOOKUP(H29,'GK IFT SDM POSTCODES'!A:A,'GK IFT SDM POSTCODES'!B:B,"") -> Neil Stebbings | K29: KEEP | L29: Strong vols and on TNT deal. Keep close and you could get another line to tip them to the 2k mark
A30: Greene King IFT | B30: Old Ship (Maldon) | G30: CM9 4RX | H30: =_xlfn.TEXTBEFORE(G30," ") -> CM9 | I30: {=LEFT(G30, MIN(IF(ISNUMBER(--MID(G30, _xlfn.SEQUENCE(LEN(G30)), 1)), _xlfn.SEQUENCE(LEN(G30)))) - 1)} -> CM | J30: =_xlfn.XLOOKUP(H30,'GK IFT SDM POSTCODES'!A:A,'GK IFT SDM POSTCODES'!B:B,"") -> Neil Stebbings | K30: GROW - Stella/SM +1 | L30: Also own Fish on Quay. Don’t buy through GK anymore
A31: Greene King IFT | B31: Old Ship (Lockhill) | G31: CM9 4RX | H31: =_xlfn.TEXTBEFORE(G31," ") -> CM9 | I31: {=LEFT(G31, MIN(IF(ISNUMBER(--MID(G31, _xlfn.SEQUENCE(LEN(G31)), 1)), _xlfn.SEQUENCE(LEN(G31)))) - 1)} -> CM | J31: =_xlfn.XLOOKUP(H31,'GK IFT SDM POSTCODES'!A:A,'GK IFT SDM POSTCODES'!B:B,"") -> Neil Stebbings
A32: Stonegate | B32: Black Rabbit | C32: 188 High Street | E32: Maldon | F32: Essex | G32: CM9 5BX | H32: =_xlfn.TEXTBEFORE(G32," ") -> CM9 | I32: {=LEFT(G32, MIN(IF(ISNUMBER(--MID(G32, _xlfn.SEQUENCE(LEN(G32)), 1)), _xlfn.SEQUENCE(LEN(G32)))) - 1)} -> CM | J32: Kellie Newell | K32: GET | L32: MO that also has Rising Sun, CM2. Evan notorisouly difficult to get ahold. TNT want this and was on Modelo hitlist
A33: Greene King IFT | B33: Jolly Sailors (Maldon) | G33: CM9 5HP | H33: =_xlfn.TEXTBEFORE(G33," ") -> CM9 | I33: {=LEFT(G33, MIN(IF(ISNUMBER(--MID(G33, _xlfn.SEQUENCE(LEN(G33)), 1)), _xlfn.SEQUENCE(LEN(G33)))) - 1)} -> CM | J33: =_xlfn.XLOOKUP(H33,'GK IFT SDM POSTCODES'!A:A,'GK IFT SDM POSTCODES'!B:B,"") -> Neil Stebbings
A34: Greene King IFT | B34: Maldon & Tiptree FC (Maldon) | G34: CM9 5JQ | H34: =_xlfn.TEXTBEFORE(G34," ") -> CM9 | I34: {=LEFT(G34, MIN(IF(ISNUMBER(--MID(G34, _xlfn.SEQUENCE(LEN(G34)), 1)), _xlfn.SEQUENCE(LEN(G34)))) - 1)} -> CM | J34: =_xlfn.XLOOKUP(H34,'GK IFT SDM POSTCODES'!A:A,'GK IFT SDM POSTCODES'!B:B,"") -> Neil Stebbings | K34: GROW - Stella/SM +1
A35: Greene King IFT | B35: Maldon & District Cons Club (Maldon | G35: CM9 6AA | H35: =_xlfn.TEXTBEFORE(G35," ") -> CM9 | I35: {=LEFT(G35, MIN(IF(ISNUMBER(--MID(G35, _xlfn.SEQUENCE(LEN(G35)), 1)), _xlfn.SEQUENCE(LEN(G35)))) - 1)} -> CM | J35: =_xlfn.XLOOKUP(H35,'GK IFT SDM POSTCODES'!A:A,'GK IFT SDM POSTCODES'!B:B,"") -> Neil Stebbings | K35: GET | L35: Buy through CMBC but good opps here
A36: Greene King IFT | B36: White Horse (Mundon) | G36: CM9 6PB | H36: =_xlfn.TEXTBEFORE(G36," ") -> CM9 | I36: {=LEFT(G36, MIN(IF(ISNUMBER(--MID(G36, _xlfn.SEQUENCE(LEN(G36)), 1)), _xlfn.SEQUENCE(LEN(G36)))) - 1)} -> CM | J36: =_xlfn.XLOOKUP(H36,'GK IFT SDM POSTCODES'!A:A,'GK IFT SDM POSTCODES'!B:B,"") -> Neil Stebbings | K36: GET
A37: Punch | B37: Chequers | C37: Church Street | E37: Maldon | G37: CM9 8AS | H37: =_xlfn.TEXTBEFORE(G37," ") -> CM9 | I37: {=LEFT(G37, MIN(IF(ISNUMBER(--MID(G37, _xlfn.SEQUENCE(LEN(G37)), 1)), _xlfn.SEQUENCE(LEN(G37)))) - 1)} -> CM | J37: Mark Nield | K37: GET
A38: Greene King IFT | B38: Forrester Park (Maldon) | G38: CM9 8EA | H38: =_xlfn.TEXTBEFORE(G38," ") -> CM9 | I38: {=LEFT(G38, MIN(IF(ISNUMBER(--MID(G38, _xlfn.SEQUENCE(LEN(G38)), 1)), _xlfn.SEQUENCE(LEN(G38)))) - 1)} -> CM | J38: =_xlfn.XLOOKUP(H38,'GK IFT SDM POSTCODES'!A:A,'GK IFT SDM POSTCODES'!B:B,"") -> Neil Stebbings | K38: GROW - Stella/SM +1 | L38: Don’t bother
A39: Greene King IFT | B39: Forrester Park Golf Club (Maldon) | G39: CM9 8EA | H39: =_xlfn.TEXTBEFORE(G39," ") -> CM9 | I39: {=LEFT(G39, MIN(IF(ISNUMBER(--MID(G39, _xlfn.SEQUENCE(LEN(G39)), 1)), _xlfn.SEQUENCE(LEN(G39)))) - 1)} -> CM | J39: =_xlfn.XLOOKUP(H39,'GK IFT SDM POSTCODES'!A:A,'GK IFT SDM POSTCODES'!B:B,"") -> Neil Stebbings | K39: GROW - Stella/SM +1 | L39: Don’t bother
A40: Greene King IFT | B40: Five Lakes Essex (Maldon) | G40: CM9 8HX | H40: =_xlfn.TEXTBEFORE(G40," ") -> CM9 | I40: {=LEFT(G40, MIN(IF(ISNUMBER(--MID(G40, _xlfn.SEQUENCE(LEN(G40)), 1)), _xlfn.SEQUENCE(LEN(G40)))) - 1)} -> CM | J40: =_xlfn.XLOOKUP(H40,'GK IFT SDM POSTCODES'!A:A,'GK IFT SDM POSTCODES'!B:B,"") -> Neil Stebbings | K40: GROW | L40: Contracted with GK. Putts and Fras look after but good for exec check and build r'ships for next tender
...

Sheet GK IFT SDM POSTCODES
A1: Postcode | B1: SDM | C1: SDM Code | D1: Email Address | E1: RSM | F1: RSM Email Address | G1: Head of Sales | H1: Local Authority | I1: County
A2: AB10 | B2: Stevie Knox | C2: 708 | D2: steve.knox@belhaven.co.uk | E2: Graham Baird | F2: graham.baird@belhaven.co.uk | G2: Graham Baird | H2: Aberdeen City | I2: Aberdeenshire
A3: AB11 | B3: Stevie Knox | C3: 708 | D3: steve.knox@belhaven.co.uk | E3: Graham Baird | F3: graham.baird@belhaven.co.uk | G3: Graham Baird | H3: Aberdeen City | I3: Aberdeenshire
A4: AB12 | B4: Stevie Knox | C4: 708 | D4: steve.knox@belhaven.co.uk | E4: Graham Baird | F4: graham.baird@belhaven.co.uk | G4: Graham Baird | H4: Aberdeen City | I4: Aberdeenshire
A5: AB13 | B5: Stevie Knox | C5: 708 | D5: steve.knox@belhaven.co.uk | E5: Graham Baird | F5: graham.baird@belhaven.co.uk | G5: Graham Baird | H5: Scotland | I5: Scotland
A6: AB14 | B6: Stevie Knox | C6: 708 | D6: steve.knox@belhaven.co.uk | E6: Graham Baird | F6: graham.baird@belhaven.co.uk | G6: Graham Baird | H6: Aberdeen City | I6: Aberdeenshire
A7: AB15 | B7: Stevie Knox | C7: 708 | D7: steve.knox@belhaven.co.uk | E7: Graham Baird | F7: graham.baird@belhaven.co.uk | G7: Graham Baird | H7: Aberdeen City | I7: Aberdeenshire
A8: AB16 | B8: Stevie Knox | C8: 708 | D8: steve.knox@belhaven.co.uk | E8: Graham Baird | F8: graham.baird@belhaven.co.uk | G8: Graham Baird | H8: Aberdeen City | I8: Aberdeenshire
A9: AB21 | B9: Stevie Knox | C9: 708 | D9: steve.knox@belhaven.co.uk | E9: Graham Baird | F9: graham.baird@belhaven.co.uk | G9: Graham Baird | H9: Aberdeen City | I9: Aberdeenshire
A10: AB22 | B10: Stevie Knox | C10: 708 | D10: steve.knox@belhaven.co.uk | E10: Graham Baird | F10: graham.baird@belhaven.co.uk | G10: Graham Baird | H10: Aberdeen City | I10: Aberdeenshire
A11: AB23 | B11: Stevie Knox | C11: 708 | D11: steve.knox@belhaven.co.uk | E11: Graham Baird | F11: graham.baird@belhaven.co.uk | G11: Graham Baird | H11: Aberdeen City | I11: Aberdeenshire
A12: AB24 | B12: Stevie Knox | C12: 708 | D12: steve.knox@belhaven.co.uk | E12: Graham Baird | F12: graham.baird@belhaven.co.uk | G12: Graham Baird | H12: Aberdeen City | I12: Aberdeenshire
A13: AB25 | B13: Stevie Knox | C13: 708 | D13: steve.knox@belhaven.co.uk | E13: Graham Baird | F13: graham.baird@belhaven.co.uk | G13: Graham Baird | H13: Aberdeen City | I13: Aberdeenshire
... A288: BS9 | B288: Steve Ikin | C288: 227 | D288: steveikin@greeneking.co.uk | E288: Alan Dawson | F288: AlanDawson@greeneking.co.uk | G288: Scott Russell | H288: Bristol, City of | I288: Bristol
A289: BT1 | B289: Out of area | C289: OOA | E289: Out of Area | F289: Out of Area | G289: Out of Area | H289: Unknown | I289: Unknown
A290: BT10 | B290: Out of area | C290: OOA | E290: Out of Area | F290: Out of Area | G290: Out of Area | H290: Unknown | I290: Unknown
A291: BT11 | B291: Out of area | C291: OOA | E291: Out of Area | F291: Out of Area | G291: Out of Area | H291: Unknown | I291: Unknown
A292: BT12 | B292: Out of area | C292: OOA | E292: Out of Area | F292: Out of Area | G292: Out of Area | H292: Unknown | I292: Unknown
A293: BT13 | B293: Out of area | C293: OOA | E293: Out of Area | F293: Out of Area | G293: Out of Area | H293: Unknown | I293: Unknown
A294: BT14 | B294: Out of area | C294: OOA | E294: Out of Area | F294: Out of Area | G294: Out of Area | H294: Unknown | I294: Unknown
A295: BT15 | B295: Out of area | C295: OOA | E295: Out of Area | F295: Out of Area | G295: Out of Area | H295: Unknown | I295: Unknown
A296: BT16 | B296: Out of area | C296: OOA | E296: Out of Area | F296: Out of Area | G296: Out of Area | H296: Unknown | I296: Unknown
A297: BT17 | B297: Out of area | C297: OOA | E297: Out of Area | F297: Out of Area | G297: Out of Area | H297: Unknown | I297: Unknown
A298: BT18 | B298: Out of area | C298: OOA | E298: Out of Area | F298: Out of Area | G298: Out of Area | H298: Unknown | I298: Unknown
A299: BT19 | B299: Out of area | C299: OOA | E299: Out of Area | F299: Out of Area | G299: Out of Area | H299: Unknown | I299: Unknown
A300: BT2 | B300: Out of area | C300: OOA | E300: Out of Area | F300: Out of Area | G300: Out of Area | H300: Unknown | I300: Unknown
... A368: BT94 | B368: Out of area | C368: OOA | E368: Out of Area | F368: Out of Area | G368: Out of Area | H368: Unknown | I368: Unknown
A369: CA1 | B369: Roy Knox | C369: 709 | D369: royknox@greeneking.co.uk | E369: Kevan Makin | F369: kevan.makin@belhaven.co.uk | G369: Graham Baird | H369: Carlisle | I369: Cumbria
A370: CA10 | B370: Roy Knox | C370: 709 | D370: royknox@greeneking.co.uk | E370: Kevan Makin | F370: kevan.makin@belhaven.co.uk | G370: Graham Baird | H370: Scotland | I370: Scotland
A371: CA11 | B371: Roy Knox | C371: 709 | D371: royknox@greeneking.co.uk | E371: Kevan Makin | F371: kevan.makin@belhaven.co.uk | G371: Graham Baird | H371: Eden | I371: Cumbria
A372: CA12 | B372: Roy Knox | C372: 709 | D372: royknox@greeneking.co.uk | E372: Kevan Makin | F372: kevan.makin@belhaven.co.uk | G372: Graham Baird | H372: Allerdale | I372: Cumbria
A373: CA13 | B373: Roy Knox | C373: 709 | D373: royknox@greeneking.co.uk | E373: Kevan Makin | F373: kevan.makin@belhaven.co.uk | G373: Graham Baird | H373: Allerdale | I373: Cumbria
A374: CA14 | B374: Roy Knox | C374: 709 | D374: royknox@greeneking.co.uk | E374: Kevan Makin | F374: kevan.makin@belhaven.co.uk | G374: Graham Baird | H374: Scotland | I374: Scotland
A375: CA15 | B375: Roy Knox | C375: 709 | D375: royknox@greeneking.co.uk | E375: Kevan Makin | F375: kevan.makin@belhaven.co.uk | G375: Graham Baird | H375: Allerdale | I375: Cumbria
A376: CA16 | B376: Roy Knox | C376: 709 | D376: royknox@greeneking.co.uk | E376: Kevan Makin | F376: kevan.makin@belhaven.co.uk | G376: Graham Baird | H376: Eden | I376: Cumbria
A377: CA17 | B377: Roy Knox | C377: 709 | D377: royknox@greeneking.co.uk | E377: Kevan Makin | F377: kevan.makin@belhaven.co.uk | G377: Graham Baird | H377: Eden | I377: Cumbria
A378: CA18 | B378: Roy Knox | C378: 709 | D378: royknox@greeneking.co.uk | E378: Kevan Makin | F378: kevan.makin@belhaven.co.uk | G378: Graham Baird | H378: Scotland | I378: Scotland
A379: CA19 | B379: Roy Knox | C379: 709 | D379: royknox@greeneking.co.uk | E379: Kevan Makin | F379: kevan.makin@belhaven.co.uk | G379: Graham Baird | H379: Scotland | I379: Scotland
A380: CA2 | B380: Roy Knox | C380: 709 | D380: royknox@greeneking.co.uk | E380: Kevan Makin | F380: kevan.makin@belhaven.co.uk | G380: Graham Baird | H380: Carlisle | I380: Cumbria
... A1016: GU9 | B1016: Dan Gathercole | C1016: 210 | D1016: danielgathercole@greeneking.co.uk | E1016: Paul Rogers | F1016: paulrogers@greeneking.co.uk | G1016: Scott Russell | H1016: Waverley | I1016: Surrey
...

Sheet Base

Sheet Multi Op LL
A1: Group | B1: POC | C1: zip | D1: district | E1: mngr/owner | F1: RTM | G1: email | H1: phone | I1: Notes
A2: distinct group | B2: cantley cock | C2: nr13 3jq | D2: =_xlfn.TEXTBEFORE(C2, " ") -> nr13 | I2: hells in may, sm always
A3: distinct group | B3: hatfield | C3: nr33 0qg | D3: =_xlfn.TEXTBEFORE(C3, " ") -> nr33 | I3: sm always - no hells
A4: distinct group | B4: kerrys | C4: nr2 4tl | D4: =_xlfn.TEXTBEFORE(C4, " ") -> nr2 | I4: hells and sm in aprl
A5: distinct group | B5: butcher bhoy | C5: nr2 1at | D5: =_xlfn.TEXTBEFORE(C5, " ") -> nr2 | I5: hells and sm in aprl
A6: distinct group | B6: stag | C6: NR13 6RW | D6: =_xlfn.TEXTBEFORE(C6, " ") -> NR13 | I6: sm in aprl - no hells
A7: distinct group | B7: oaklands | C7: NR7 0HH | D7: =_xlfn.TEXTBEFORE(C7, " ") -> NR7 | I7: hells in aprl and sm always
A8: distinct group | B8: sole and heel | C8: NR13 6QH | D8: =_xlfn.TEXTBEFORE(C8, " ") -> NR13 | I8: hells in aprl and sm feb
A9: moss and co | B9: henham barns | C9: NR34 8AQ | D9: =_xlfn.TEXTBEFORE(C9, " ") -> NR34 | F9: GK IFT | I9: no bbg
A10: moss and co | B10: angel | C10: nr34 8rl | D10: =_xlfn.TEXTBEFORE(C10, " ") -> nr34 | E10: amelia and eliza | F10: GK IFT | I10: san mig and stella on -(didn’t see stella on last, but on vols-missed?) carlsberg dip, ops for BL?
A11: moss and co | B11: bell | C11: nr33 8jr | D11: =_xlfn.TEXTBEFORE(C11, " ") -> nr33 | E11: harley gm baily am | F11: GK IFT | I11: sm on, and stella -(didn’t see stella on last, but on vols- missed?) replace with adnams
A12: moss and co | B12: harbour | C12: nr33 0ag | D12: =_xlfn.TEXTBEFORE(C12, " ") -> nr33 | F12: GK IFT | I12: stella and sm on
A13: moss and co | B13: jolly sailors | C13: nr33 0js | D13: =_xlfn.TEXTBEFORE(C13, " ") -> nr33 | E13: adam mngr, sarah am | F13: GK IFT | I13: SM and Stella on - Hells and BL on mobile
A14: moss and co | B14: broadlands | C14: NR33 9JY | D14: =_xlfn.TEXTBEFORE(C14, " ") -> NR33 | E14: abby mngr tina am | F14: GK IFT | I14: sanmig and stella pouring -hells ops, packaged is good
A15: moss and co | B15: vilage maid | C15: NR32 5LP | D15: =_xlfn.TEXTBEFORE(C15, " ") -> NR32 | E15: rachel gm, kyle am | F15: GK IFT | I15: Sm on, no stella but any ops?
A16: moss and co | B16: white horse | C16: IP13 8JR | D16: =_xlfn.TEXTBEFORE(C16, " ") -> IP13 | E16: niki tender, em gm | F16: GK IFT | I16: stella and sm on, stella was on churn watch, bobbie said ops for kop
A17: moss and co | B17: Commodore | C17: NR32 3NF | D17: =_xlfn.TEXTBEFORE(C17, " ") -> NR32 | E17: Tom mngr, bobbie ho | F17: Stonegate
A18: Norwich Inns | B18: Alexandra Tavern | C18: NR2 3BB | D18: =_xlfn.TEXTBEFORE(C18, " ") -> NR2 | E18: Craig McLaren CEO | F18: ift | G18: secretary@norwichinns.co.uk | H18: 07799 530152 01603 627772 | I18: https://www.norwichinns.com/ flag from sdm, working on propsoal
A19: Norwich Inns | B19: Annesley House Hotel, Norwich | C19: nr2 2la | D19: =_xlfn.TEXTBEFORE(C19, " ") -> nr2 | E19: Craig McLaren CEO
A20: Norwich Inns | B20: Black Boys Hotel | C20: nr11 6eh | D20: =_xlfn.TEXTBEFORE(C20, " ") -> nr11 | E20: Craig McLaren CEO | H20: 01263 732122
A21: Norwich Inns | B21: Blue Boar | C21: nr7 8rl | D21: =_xlfn.TEXTBEFORE(C21, " ") -> nr7 | E21: Craig McLaren CEO | H21: 1603426802
A22: Norwich Inns | B22: Brick Kilns | C22: nr13 5jh | D22: =_xlfn.TEXTBEFORE(C22, " ") -> nr13 | E22: Craig McLaren CEO | H22: (01603) 720043
A23: Norwich Inns | B23: California Tavern | C23: nr29 3qw | D23: =_xlfn.TEXTBEFORE(C23, " ") -> nr29 | E23: Craig McLaren CEO | H23: 01493 730340
A24: Norwich Inns | B24: Coach & Horses | C24: nr1 1ba | D24: =_xlfn.TEXTBEFORE(C24, " ") -> nr1 | E24: Craig McLaren CEO | H24: 1603477077
A25: Norwich Inns | B25: Countryman | C25: nr15 1ns | D25: =_xlfn.TEXTBEFORE(C25, " ") -> nr15 | E25: Craig McLaren CEO | H25: 01508 470946
A26: Norwich Inns | B26: Dales Hotel | C26: nr26 8tj | D26: =_xlfn.TEXTBEFORE(C26, " ") -> nr26 | E26: Craig McLaren CEO | H26: 01263 824555
A27: Norwich Inns | B27: Dog Inn | C27: nr29 5ny | D27: =_xlfn.TEXTBEFORE(C27, " ") -> nr29 | E27: Craig McLaren CEO | H27: 01692 631041
A28: Norwich Inns | B28: Dolphin Club | C28: nr29 4jd | D28: =_xlfn.TEXTBEFORE(C28, " ") -> nr29 | E28: Craig McLaren CEO
A29: Norwich Inns | B29: Eaton Golf Club | C29: nr4 6sf | D29: =_xlfn.TEXTBEFORE(C29, " ") -> nr4 | E29: Craig McLaren CEO | H29: 01603 251395
A30: Norwich Inns | B30: Furzedown Hotel | C30: NR30 4EN | D30: =_xlfn.TEXTBEFORE(C30, " ") -> NR30 | E30: Craig McLaren CEO | H30: 01493 844138
A31: Norwich Inns | B31: George Hotel. Norwich | C31: NR2 2DA | D31: =_xlfn.TEXTBEFORE(C31, " ") -> NR2 | E31: Craig McLaren CEO | H31: 1603617841
A32: Norwich Inns | B32: Glen Lodge Bawburgh Golf Club | C32: NR9 3LU | D32: =_xlfn.TEXTBEFORE(C32, " ") -> NR9 | E32: Craig McLaren CEO
A33: Norwich Inns | B33: Kings Arms | C33: NR30 1BG | D33: =_xlfn.TEXTBEFORE(C33, " ") -> NR30 | E33: Craig McLaren CEO
A34: Norwich Inns | B34: Kings Head Bawburgh | C34: NR9 3LS | D34: =_xlfn.TEXTBEFORE(C34, " ") -> NR9 | E34: Craig McLaren CEO | H34: 01603 744977
A35: Norwich Inns | B35: Kings Head, Loddon | C35: NR14 6EZ | D35: =_xlfn.TEXTBEFORE(C35, " ") -> NR14 | E35: Craig McLaren CEO | H35: 01508 520330
A36: Norwich Inns | B36: Kings Head. Ashwellthorpe | C36: NR12 7EA | D36: =_xlfn.TEXTBEFORE(C36, " ") -> NR12 | E36: Craig McLaren CEO | H36: 01603 737426
A37: Norwich Inns | B37: Links Hotel | C37: NR27 9QH | D37: =_xlfn.TEXTBEFORE(C37, " ") -> NR27 | E37: Craig McLaren CEO | H37: 01263 838383
A38: Norwich Inns | B38: Merlins | C38: NR30 2EJ | D38: =_xlfn.TEXTBEFORE(C38, " ") -> NR30 | E38: Craig McLaren CEO
A39: Norwich Inns | B39: Park Farm Hotel | C39: NR9 3DL | D39: =_xlfn.TEXTBEFORE(C39, " ") -> NR9 | E39: Craig McLaren CEO | H39: 01603 810264
A40: Norwich Inns | B40: Pier Hotel | C40: NR31 6PL | D40: =_xlfn.TEXTBEFORE(C40, " ") -> NR31 | E40: Craig McLaren CEO | H40: 01493 662631
...

Sheet CAT

Sheet Ox. Brewers Ipswich
C2: Ipswhich | D2: 2024 | E2: 2025 | G2: September 24 v 25 | L2: Hells
C3: BBG Market Share | D3: 0.072996257 | E3: 0.068302981 | L3: +17.5% Pints YOY
B5: BDM | C5: Ipswhich | D5: 2024 | F5: 2025
D6: Pints | E6: Stockists | F6: Pints | G6: % change v 24 | H6: Stockists | I6: % change v 24
B7: TOTAL | C7: Total Draught Sales | D7: 6621783.4 | E7: 215 | F7: 6500258 | G7: -0.018352367 | H7: 215 | I7: -1
C8: Total Draught Beer | D8: 6011868.1 | E8: 215 | F8: 5884139 | G8: -0.021246158 | H8: 215 | I8: -1
C9: Total BBG | D9: 483365.4 | E9: 100 | F9: 443987 | G9: -0.081467147 | H9: 90 | I9: -11
C10: Total CMBC | D10: 553047.4 | E10: 95 | F10: 509190.8 | G10: -0.079299894 | H10: 103 | I10: 7
C11: Total Molson Coors | D11: 1158371.3 | E11: 172 | F11: 969650.3 | G11: -0.16291926 | H11: 156 | I11: -17
C12: Total Heineken UK | D12: 2139576.1 | E12: 194 | F12: 2303465.2 | G12: 0.076598865 | H12: 198 | I12: 3
C13: Total All Other | D13: 2287416.4 | E13: 214 | F13: 2273949.5 | G13: -0.0058873846 | H13: 214 | I13: -1
B14: CORE LAGER | C14: Total Lager | D14: 3706048.8 | E14: 215 | F14: 3613502.4 | G14: -0.024971717 | H14: 215 | I14: -1
C15: Total Core Lager | D15: 887698.1 | E15: 137 | F15: 769456.4 | G15: -0.13320035 | H15: 136 | I15: -2
C16: Total Bud Light | D16: 1455.7 | E16: 1 | H16: 0 | I16: -2
C17: Total Carling | D17: 149133.3 | E17: 32 | F17: 115488.2 | G17: -0.22560421 | H17: 28 | I17: -5
C18: Total Carlsberg Pilsner | D18: 223880.5 | E18: 38 | F18: 199734.4 | G18: -0.10785263 | H18: 41 | I18: 2
C19: Total Fosters | D19: 504205.3 | E19: 88 | F19: 444722.5 | G19: -0.11797337 | H19: 85 | I19: -4
C20: Total Tennents Lager | E20: 0 | H20: 0 | I20: -1
B21: PREMIUM 4% | C21: Total World 4% | D21: 443418.2 | E21: 109 | F21: 386535.3 | G21: -0.12828274 | H21: 109 | I21: -1
C22: Total Amstel | D22: 222533 | E22: 55 | F22: 214966.1 | G22: -0.034003496 | H22: 64 | I22: 8
C23: Total Becks Vier | D23: 16436.4 | E23: 4 | F23: 8847.6 | G23: -0.46170694 | H23: 4 | I23: -1
C24: Total Coors | D24: 135976.2 | E24: 34 | F24: 97493.1 | G24: -0.2830135 | H24: 24 | I24: -11
C25: Total Grolsch 4% | E25: 0 | H25: 0 | I25: -1
C26: Total Heineken Silver | D26: 2288.7 | E26: 1 | F26: 441.9 | G26: -0.80692096 | H26: 0 | I26: -2
C27: Total Kozel | E27: 0 | H27: 0 | I27: -1
C28: Total Pravha | D28: 66183.4 | E28: 21 | F28: 64786.6 | G28: -0.02110499 | H28: 22 | I28: 0
B29: PREMIUM LAGER | C29: Total Premium Lager | D29: 619091.4 | E29: 114 | F29: 595424.6 | G29: -0.038228281 | H29: 118 | I29: 3
C30: Total Budweiser | D30: 14992 | E30: 5 | F30: 9411.5 | G30: -0.37223186 | H30: 2 | I30: -4
C31: Total Carlsberg Export | D31: 233864 | E31: 42 | F31: 218752.9 | G31: -0.064614904 | H31: 40 | I31: -3
C32: Total Heineken | D32: 69973.9 | E32: 24 | F32: 75620.4 | G32: 0.080694373 | H32: 24 | I32: -1
C33: Total Kronenbourg 1664 | D33: 83805.8 | E33: 19 | F33: 74861.5 | G33: -0.1067265 | H33: 25 | I33: 5
C34: Total San Miguel | D34: 196150.9 | E34: 48 | F34: 174336 | G34: -0.11121489 | H34: 36 | I34: -13
C35: Total Stella Artois | D35: 216451.5 | E35: 50 | F35: 216774.8 | G35: 0.0014936371 | H35: 54 | I35: 3
B36: WORLD LAGER | C36: Total World Beer | D36: 1755829.3 | E36: 212 | F36: 1862078.8 | G36: 0.060512431 | H36: 212 | I36: -1
C37: Total Asahi | D37: 24460 | E37: 5 | F37: 24004.2 | G37: -0.018634505 | H37: 6 | I37: 0
C38: Total Birra Moretti | D38: 646122.6 | E38: 136 | F38: 656705.6 | G38: 0.016379244 | H38: 138 | I38: 1
C39: Total Camden Hells Lager | D39: 14994.5 | E39: 8 | F39: 17611.2 | G39: 0.17451065 | H39: 12 | I39: 3
C40: Total Cobra | D40: 428.7 | E40: 0 | H40: 0 | I40: -1
C41: Total Corona Extra | D41: 5755.2 | E41: 3 | F41: 2591.4 | G41: -0.54972894 | H41: 4 | I41: 0
C42: Total Estrella Damm | D42: 65483.2 | E42: 13 | F42: 46210.2 | G42: -0.29431976 | H42: 16 | I42: 2
...

Sheet Ox. Brewers All Patches
A1: Oxford Partnership | Monthly BDM Volumes Tracker YTD
A2: Source: Oxford Market Watch | Volumes Tracker (September 2025 ) | O2: BDM | P2: 2024 | Q2: 2025
O3: BBG Market Share | P3: 0.051252919 | Q3: 0.047677269
A4: © The Oxford Partnership Limited 2025
O5: Birmingham | P5: 0.043408923 | Q5: 0.038286454
O6: Bournemouth | P6: 0.069194017 | Q6: 0.06569989
O7: Bristol | P7: 0.046398515 | Q7: 0.046686891
O8: Cambridge / Home Counties | P8: 0.076356892 | Q8: 0.073232704
J9: Camden Pale | K9: Mahou | L9: Bud Light | M9: Stella Artois | O9: Cardiff | P9: 0.081842083 | Q9: 0.076331625
B10: (All) | C10: 2024 | D10: 2025 | J10: +11% Pints YOY | K10: +400% Pints YOY | L10: +37.3% Pints YOY | M10: +4.5% Pint vs Moretti YOY | O10: Edinburgh / Glasgow | P10: 0.017579566 | Q10: 0.016178909
B11: BBG Market Share | C11: 0.051252919 | D11: 0.047677269 | J11: Punk -28% | K11: EstrellaD -12.2% | L11: CARLS -10.3% | M11: +3.7% Pint vs HUK YOY | O11: Exeter | P11: 0.046153675 | Q11: 0.028592319
J12: Neckoil -11% | K12: Madri -14.8% | L12: Calring -12% | O12: Ipswhich | P12: 0.072996257 | Q12: 0.068302981
A13: BDM | B13: (All) | C13: 2024 | E13: 2025 | L13: Fosters -11.3% | O13: Leeds & York | P13: 0.032407228 | Q13: 0.028396956
C14: Pints | D14: Stockists | E14: Pints | F14: % change v 24 | G14: Stockists | H14: % change v 24 | O14: Leicester | P14: 0.049390634 | Q14: 0.04638525
A15: TOTAL | B15: Total Draught Sales | C15: 3.1254079e+08 | D15: 8315 | E15: 3.0120319e+08 | F15: -0.03627559 | G15: 8146 | H15: -169 | O15: Liverpool | P15: 0.049617583 | Q15: 0.050016743
B16: Total Draught Beer | C16: 2.8093009e+08 | D16: 8312 | E16: 2.6998843e+08 | F16: -0.038947985 | G16: 8144 | H16: -168 | O16: Manchester | P16: 0.054458544 | Q16: 0.050752933
B17: Total BBG | C17: 16018628 | D17: 3134 | E17: 14360546 | F17: -0.10350964 | G17: 2691 | H17: -443 | O17: Newcastle | P17: 0.04716445 | Q17: 0.045636982
B18: Total CMBC | C18: 9355299.8 | D18: 1987 | E18: 9093699.6 | F18: -0.027962781 | G18: 2071 | H18: 84 | O18: North London | P18: 0.058969087 | Q18: 0.051544093
B19: Total Molson Coors | C19: 65275950 | D19: 5546 | E19: 56944375 | F19: -0.12763622 | G19: 5290 | H19: -256 | O19: Nottingham | P19: 0.052296451 | Q19: 0.043491484
B20: Total Heineken UK | C20: 1.0770079e+08 | D20: 7657 | E20: 1.0696427e+08 | F20: -0.0068385525 | G20: 7561 | H20: -96 | O20: Reading | P20: 0.045816082 | Q20: 0.043491484
B21: Total All Other | C21: 1.1418978e+08 | D21: 8217 | E21: 1.1383916e+08 | F21: -0.0030704518 | G21: 8049 | H21: -168 | O21: Sheffield | P21: 0.04943343 | Q21: 0.049934006
A22: CORE LAGER | B22: Total Lager | C22: 1.761406e+08 | D22: 8292 | E22: 167665470 | F22: -0.048115723 | G22: 8122 | H22: -170 | O22: South London | P22: 0.062246764 | Q22: 0.062134626
B23: Total Core Lager | C23: 68309799 | D23: 6476 | E23: 61078714 | F23: -0.10585722 | G23: 6260 | H23: -216 | O23: Southampton | P23: 0.054214283 | Q23: 0.054551717
B24: Total Bud Light | C24: 21826.8 | D24: 7 | E24: 29962.6 | F24: 0.3727436 | G24: 12 | H24: 5 | O24: Truro | P24: 0.050528123 | Q24: 0.019332983
B25: Total Carling | C25: 32917625 | D25: 3665 | E25: 28957905 | F25: -0.12029177 | G25: 3484 | H25: -181
B26: Total Carlsberg Pilsner | C26: 2476603.7 | D26: 441 | E26: 2222127.8 | F26: -0.10275197 | G26: 458 | H26: 17
B27: Total Fosters | C27: 25447024 | D27: 3263 | E27: 22575373 | F27: -0.11284821 | G27: 3100 | H27: -163
B28: Total Tennents Lager | C28: 6889335.5 | D28: 375 | E28: 6678194.6 | F28: -0.030647499 | G28: 360 | H28: -15
A29: PREMIUM 4% | B29: Total World 4% | C29: 23183877 | D29: 4834 | E29: 19782741 | F29: -0.14670266 | G29: 4390 | H29: -444
B30: Total Amstel | C30: 9990738.6 | D30: 2417 | E30: 9059362.8 | F30: -0.093223918 | G30: 2299 | H30: -118
B31: Total Becks Vier | C31: 157992.7 | D31: 40 | E31: 123215 | F31: -0.2201222 | G31: 31 | H31: -9
B32: Total Coors | C32: 10584640 | D32: 2038 | E32: 8556331.1 | F32: -0.19162758 | G32: 1754 | H32: -284
B33: Total Grolsch 4% | C33: 23881.4 | D33: 8 | E33: 23885.9 | F33: 0.00018843116 | G33: 13 | H33: 5
B34: Total Heineken Silver | C34: 342811 | D34: 142 | E34: 71268.8 | F34: -0.79210469 | G34: 5 | H34: -137
B35: Total Kozel | C35: 0 | D35: 0 | E35: 0 | F35: 0 | G35: 0 | H35: 0
B36: Total Pravha | C36: 2074048.6 | D36: 523 | E36: 1927002.5 | F36: -0.070898098 | G36: 512 | H36: -11
A37: PREMIUM LAGER | B37: Total Premium Lager | C37: 17466646 | D37: 3528 | E37: 16805373 | F37: -0.03785922 | G37: 3539 | H37: 11
B38: Total Budweiser | C38: 131253.4 | D38: 43 | E38: 122606.8 | F38: -0.065877151 | G38: 37 | H38: -6
B39: Total Carlsberg Export | C39: 1976826.2 | D39: 357 | E39: 1835532.4 | F39: -0.071475075 | G39: 347 | H39: -10
B40: Total Heineken | C40: 3386888 | D40: 982 | E40: 3168372 | F40: -0.064518224 | G40: 1019 | H40: 37
...

Sheet Push

Sheet Pipeline, RM Push, Visit Ops
A1: outlet_name | B1: zipcode | C1: sector | D1: district | E1: RTM | F1: RM | G1: Landlords | H1: email | I1: contact | J1: Group? | K1: Notes | L1: Brand in | M1: why - staci/lead/rm/whoopsie | N1: BDM TODO
A2: Angel | B2: NR34 8RL | C2: =LEFT(B2,2) -> NR | D2: =_xlfn.TEXTBEFORE(B2, " ") -> NR34 | E2: GK IFT | F2: adam vass | G2: Eliza & amelia | I2: 770107725 | K2: later afternoons best, Thursdays better. prebook carlberg had a vol dip perhaps ops for bl. not tied fully to gk. | M2: lead mid | N2: call visit
A3: attleboro football | B3: nr17 2as | C3: =LEFT(B3,2) -> nr | D3: =_xlfn.TEXTBEFORE(B3, " ") -> nr17 | E3: Greene King | F3: reddit | G3: emma | I3: 44 7584 073258 | K3: £121.36+VAT for tnt | M3: install fu | N3: want tnt?
A4: bath house | B4: co14 8pz | C4: =LEFT(B4,2) -> co | D4: =_xlfn.TEXTBEFORE(B4, " ") -> co14 | E4: Greene King | F4: nikki | G4: kish | M4: install fu
A5: belle vue | B5: nr2 3bl | C5: =LEFT(B5,2) -> nr | D5: =_xlfn.TEXTBEFORE(B5, " ") -> nr2 | E5: Stonegate | F5: Galloway | G5: david | I5: 7545340923 | J5: y | K5: golden thorpe group (and cellar house). Wants mahoue ipo madri (modelo and eazy also in talks as of dec. 1) | L5: eazy/mahou | M5: lead high
A6: Belstead Arms | B6: IP2 9QU | C6: =LEFT(B6,2) -> IP | D6: =_xlfn.TEXTBEFORE(B6, " ") -> IP2 | E6: Stonegate | F6: pitt | G6: Emma and Darren (penny sister) | I6: 07707859243 | M6: lead low
A7: Bull | B7: NR19 1DZ | C7: =LEFT(B7,2) -> NR | D7: =_xlfn.TEXTBEFORE(B7, " ") -> NR19 | E7: greene King IFT | F7: JARVIS | G7: nigel | I7: 7920113861 | K7: pale installing ipo Level - lvm x2 nov 26 | M7: install fu
A8: Cock Horse | B8: CO10 9SA | C8: =LEFT(B8,2) -> CO | D8: =_xlfn.TEXTBEFORE(B8, " ") -> CO10 | E8: Stonegate | G8: kev and becca | H8: info@thecockhorse.co.uk | J8: y | K8: very sp site, not really tnt, bella pubs (previously not replyed via email/phone Bunbury arms ip33, linden tree ip33- both (gk l&t), and three kings inn -fornham all saints | M8: lead low
A9: Crown | B9: ip14 4bq | C9: =LEFT(B9,2) -> ip | D9: =_xlfn.TEXTBEFORE(B9, " ") -> ip14 | E9: gk ift | G9: lee | M9: install fu
A10: Crown | B10: CO11 1AH | C10: =LEFT(B10,2) -> CO | D10: =_xlfn.TEXTBEFORE(B10, " ") -> CO11 | E10: GK L&T | F10: Pearson | G10: Matt | J10: y | K10: Stella likely, works at alma. Rm push promised | L10: Stella | M10: lead mid
A11: falcon | B11: ip11 9ds | C11: =LEFT(B11,2) -> ip | D11: =_xlfn.TEXTBEFORE(B11, " ") -> ip11 | E11: Admiral | F11: mciver | M11: lead low | N11: rm help
A12: four horseshoes | B12: ip23 8hd | C12: =LEFT(B12,2) -> ip | D12: =_xlfn.TEXTBEFORE(B12, " ") -> ip23 | E12: GK IFT | F12: rob brown | G12: tom | K12: SM new in march, stella ipo reti ops - call | M12: install fu | N12: rm help
A13: Fox | B13: ip31 1rd | C13: =LEFT(B13,2) -> ip | D13: =_xlfn.TEXTBEFORE(B13, " ") -> ip31 | E13: gk ift | F13: kate | G13: harrison | K13: tnt pending, stella new… open ops | M13: install fu | N13: tnt/lead fu
A14: Garden House | B14: nr16 2by | C14: =LEFT(B14,2) -> nr | D14: =_xlfn.TEXTBEFORE(B14, " ") -> nr16 | E14: gk ift | F14: adam vass | K14: aka smokehouse, churned and back | M14: install fu
A15: Glen Lodge Golf and Wedding Center | B15: NR9 3LU | C15: =LEFT(B15,2) -> NR | D15: =_xlfn.TEXTBEFORE(B15, " ") -> NR9 | E15: Greene King | G15: lou | H15: lou@bawburgh.com | M15: lead mid
A16: golden star | B16: nr3 1dd | C16: =LEFT(B16,2) -> nr | D16: =_xlfn.TEXTBEFORE(B16, " ") -> nr3 | E16: GK L&T | F16: Jarvis | G16: Leva | I16: 7897305379 | K16: leva - leva to wahts app me a good date for next week , as on holiday this. call to confirm visit next Thursday after 5 . Stella best fit - but says no? happy for a chat but more kop btl and 0%... Push camden light ops (data lead) | M16: lead mid
A17: Greyhound (Lavenham) | B17: CO10 9PZ | C17: =LEFT(B17,2) -> CO | D17: =_xlfn.TEXTBEFORE(B17, " ") -> CO10 | E17: GK L&T | G17: sally | H17: info@greyhoundlavenham.co.uk | K17: Sally in tomorrow, (Keighley?) tender shared email to book in. slammed for mid day and good vibes. ops for fruit cider swap to stella or hells. | M17: lead low
A18: Hare Inn Long Melford | B18: CO10 9DF | C18: =LEFT(B18,2) -> CO | D18: =_xlfn.TEXTBEFORE(B18, " ") -> CO10 | E18: GK L&T | F18: Sam | G18: nik and kate | K18: rose is kates sister. - either can be dm. tori tender checked upstairs but kate is out. haven't changed up the bar since I was here this time LY. emailing. Peroni ops | M18: lead low
A19: Hintlesham Community Hall | B19: ip8 3ps | C19: =LEFT(B19,2) -> ip | D19: =_xlfn.TEXTBEFORE(B19, " ") -> ip8 | E19: gk ift | G19: jim | I19: 7768462492 | M19: install fu
A20: Horringer Social Club | B20: ip29 5ru | C20: =LEFT(B20,2) -> ip | D20: =_xlfn.TEXTBEFORE(B20, " ") -> ip29 | E20: gk ift | G20: John | I20: 07802 912704 | K20: hells installed | M20: install fu
A21: Hudson | B21: CO1 1NX | C21: =LEFT(B21,2) | D21: =_xlfn.TEXTBEFORE(B21, " ") -> CO1 | E21: gk ift | F21: joe sagnella | G21: henry | I21: 7974132616 | K21: also o n churn? | L21: becks oct flag | M21: install confirm
A22: Kings arms | B22: CO7 7DJ | E22: Stonegate | K22: 2 foc frome harry | M22: protect
A23: Kings Head | B23: CO10 0JE | C23: =LEFT(B23,2) -> CO | D23: =_xlfn.TEXTBEFORE(B23, " ") -> CO10 | E23: GK L&T | F23: Sam | M23: lead low
A24: Lifeboat | B24: NR12 0AL | C24: =LEFT(B24,2) -> NR | D24: =_xlfn.TEXTBEFORE(B24, " ") -> NR12 | E24: GK IFT | F24: Galpin | G24: Matt | K24: customer lvm with landline, tried twice lvm no resposne. Has SM | M24: lead mid
A25: Mouse trap | B25: nr1 1bg | C25: =LEFT(B25,2) -> nr | D25: =_xlfn.TEXTBEFORE(B25, " ") -> nr1 | E25: gk ift | K25: site not on google? Sdm reddit? | L25: stella & becks on dec flags | M25: install confirm
A26: norfolk terrier | B26: IP24 1TA | C26: =LEFT(B26,2) -> IP | D26: =_xlfn.TEXTBEFORE(B26, " ") -> IP24 | E26: GK L&T | F26: Jarvis | G26: Tish | I26: 7799491049 | K26: HIVE TO LEASED IN FEB | L26: Stella | M26: lead low
A27: Old Red House | B27: NR33 8JP | C27: =LEFT(B27,2) -> NR | D27: =_xlfn.TEXTBEFORE(B27, " ") -> NR33 | E27: Stonegate | G27: TINA | I27: 7780430669 | K27: Tina on hols until sept 27, one carling drinker, has x3 coor to attack dupes, neckoil does well but ££, no tnt but ops as just too costly | M27: lead mid
A28: Old times | B28: IP4 5NJ | C28: ip | D28: =_xlfn.TEXTBEFORE(B28, " ") -> IP4 | E28: GK IFT | F28: Kate | M28: protect | N28: tnt cancelled?
A29: Parkhill Hotel | B29: NR32 5DQ | C29: =LEFT(B29,2) -> NR | D29: =_xlfn.TEXTBEFORE(B29, " ") -> NR32 | E29: CMBC | F29: Rob | G29: Ruth pwmer (noel daughters wife and bar manager) | H29: mail@parkhillhotel.co.uk | K29: function weeks- 32pints in one pod- uses 6-7 pods (estrella mainly).. 3 kegs a week outside of events. noel is married to the daughter of the owners. from Pennsylvania. met her wife at Disney and moved here. she's happy for a meet to explore options. feels the carlsberg Dispense system is limited on choice to be able to switch up. sanmig sold well but delisted on the Dispense system and estrella is much more ££...but volumes are the same. worried to remove Dispense system. as goes through little volumes and saves on wastage. but up to explore. will share with sdm and see ops, not likely to be of worth for gk tbd. lots of packaged options and easier for them. | M29: lead mid | N29: rm fu
A30: Plough | B30: NR32 5AN | C30: =LEFT(B30,2) -> NR | D30: =_xlfn.TEXTBEFORE(B30, " ") -> NR32 | E30: PROSPECT IFT | F30: Rob | G30: dan ll a nd Dawn tender | H30: info@ploughinn-blundeston.co.uk | J30: y | K30: has three other pubs: bell st olives the priory (seasonal pub)- opposite the bell. Wavley river center - towards Beccles alpaca newest, inches new ipo aspall. cruz and oil top vol, the cask. | M30: lead mid
A31: Pot Black | B31: ip33 1yq | C31: =LEFT(B31,2) -> ip | D31: =_xlfn.TEXTBEFORE(B31, " ") -> ip33 | E31: gk ift | F31: kate | G31: andy | K31: tnt sorted on $? Vianet is sorted. Screenprojecter requested w fraser | L31: bl ipo cmbc | M31: lead high | N31: tnt price sorted?
A32: queens head stowmarket | B32: IP14 1EF | C32: =LEFT(B32,2) -> IP | D32: =_xlfn.TEXTBEFORE(B32, " ") -> IP14 | E32: punch | G32: michael and d | I32: 7702177636 | K32: stella on - sm off in jan ipo cruz. Open to stout ipo guin…or next to for foc, and fancy differiancion…x 1/2 keg a week of G remove -or if dear, atlantic doing no sells and do both stouts for trail and margin play -rm require postbox | L32: stout | M32: lead high | N32: lead fu
A33: Rose & Crown Hotel | B33: CO1 2TZ | C33: =LEFT(B33,2) -> CO | D33: =_xlfn.TEXTBEFORE(B33, " ") -> CO1 | E33: CMBC | F33: nikki | G33: ilza | H33: ilze.iriste@rose-and-crown.com | K33: ealza. is bar manager and wedding manager... walked in whilst a bride was walking down the isle.... lots of crying. reception says she's super easy going and likely to chat, sending email off cmbc list. couldn't see bar as wedding, tbd | M33: lead low
A34: Royal British Legion Club | B34: IP14 1PH | C34: =LEFT(B34,2) -> IP | D34: =_xlfn.TEXTBEFORE(B34, " ") -> IP14 | E34: Greene King | G34: kelly bar manager (sue secratary) | M34: lead mid | N34: get quotes
A35: Royal George | B35: IP31 1DD | C35: =LEFT(B35,2) -> IP | D35: =_xlfn.TEXTBEFORE(B35, " ") -> IP31 | E35: Admiral | G35: bob and nick | K35: asked to fu ops in early november | M35: lead mid
A36: sailors home | B36: nr33 7sb | C36: =LEFT(B36,2) -> nr | D36: =_xlfn.TEXTBEFORE(B36, " ") -> nr33 | E36: gk ift | K36: has sm on font, gk led pub | L36: becks in dec flags | M36: install confirm
A37: seaspan | B37: co15 1un | C37: =LEFT(B37,2) -> co | D37: =_xlfn.TEXTBEFORE(B37, " ") -> co15 | E37: Greene King | F37: nikki | G37: chris | M37: install fu
A38: Swan Hotel Lavenham | B38: CO10 9QA | C38: =LEFT(B38,2) -> CO | D38: =_xlfn.TEXTBEFORE(B38, " ") -> CO10 | E38: PROSPECT IFT | G38: james sanders gm- gillian bar mngr dm | H38: gillian.murgia@theswanatlavenham.co.uk | J38: y | K38: freddy, very quiet shy youngster behind the bar. doesn't know much of the trading vibe but passed on email for mngr and sending email. has a x3 joints, others are restraunt and spa. tbd on ops | M38: lead low
A39: Swan Inn | B39: IP21 5AS | C39: =LEFT(B39,2) -> IP | D39: =_xlfn.TEXTBEFORE(B39, " ") -> IP21 | E39: Stonegate | F39: pitt | G39: new management tbd | M39: lead low | N39: rm help
A40: swan | B40: ip21 5pe | C40: =LEFT(B40,2) -> ip | D40: =_xlfn.TEXTBEFORE(B40, " ") -> ip21 | E40: gk ift | G40: mick | I40: 73941740453 | K40: san mig ipo madri, new accout | M40: install fu
...

Sheet TopVol
A1: RTM | B1: POC | C1: Zip | D1: Brand(s) | E1: 2025 TTL VOL | F1: Volume YoY | G1: Group? | H1: DM | I1: Notes | J1: TODO
A2: GK IFT | B2: White Horse (Corton) | C2: NR32 5HP | D2: 10gl Stella Artois 4.6, 11G 50L San Miguel Grundy 5.0 | E2: 92.3446 | H2: Lisa (tasha AM) | I2: wee bit out of the way to drive to. 2max kegs a week per brand. carling, aspall, target.. add with tnt ops. more cafe restraunt clientel | J2: tnt
A3: GK IFT | B3: Potters Leisure Ltd (Gt Yarmouth) | C3: NR31 9BX | D3: 10gl Stella Artois 4.6 11G/50L Becks Vier 4.0 11G/50L Budweiser Draught 4.5 | E3: 467.5726 | J3: never visited
A4: GK IFT | B4: Number 1 Bar & Kitchen (Gorleston) | C4: NR31 6DA | D4: 10gl Stella Artois 4.6 11G/50L Budweiser Draught 4.5 11G/50L San Miguel Grundy 5.0 | E4: 116.8384 | I4: SDM just asked for foc for cheap stella jan deal | J4: …fraser foc call sdm
A5: GK IFT | B5: Norwich City Football Club (Norwich | C5: NR1 1JE | D5: 11G/50L Camden Hells Lager 4.6 30ltr Kopparberg Strawb & Lime 4.0 | E5: 204.3 | I5: SDM Neil deals with, do reach out to support
A6: GK IFT | B6: Little Wellington (Stowmarket) | C6: IP14 5AG | D6: 10gl Stella Artois 4.6 11G/50L San Miguel Grundy 5.0 | E6: 96.0568 | H6: Pete (AKA FRIDGE) | I6: unlikely ops. Brands swell. Not tnt want of vianet tracking
A7: GK IFT | B7: Kings Arms Hotel (North Walsham) | C7: NR28 9JX | D7: 10gl Stella Artois 4.6 11G/50L Camden Hells Lager 4.6 11G/50L San Miguel Grundy 5.0 | E7: 153.0314 | H7: Sarah (dad Martin Miles) | I7: gk stole from lacons, sdm ticked off at wam. Hates lacons cellar serivces
A8: GK IFT | B8: Jolly Sailors (Lowestoft) | C8: NR33 0JS | D8: 10gl Stella Artois 4.6 30ltr Camden Hells Lager 4.6 11G/50L Bud Light 3.4 11G/50L San Miguel Grundy 5.0 | E8: 171.686 | G8: Moss & Co | H8: adam mngr sarah am
A9: GK IFT | B9: JD Young Hotel (Harleston) | C9: IP20 9AD | D9: 10gl Stella Artois 4.6 11G/50L Bud Light 3.4 11G/50L San Miguel Grundy 5.0 | E9: 127.3268 | H9: beth owner, Ella mngr | I9: doesn’t want team to know white label is BL. Agreed listing fee with sdm, no one answered to sign… asked for tnt? Sorted? Oooold | J9: listing fee
A10: GK IFT | B10: Frinton On Sea War Memorial Club | C10: CO13 9EB | D10: 10gl Stella Artois 4.6 11G/50L San Miguel Grundy 5.0 | E10: 102.2356 | J10: never visited
A11: GK IFT | B11: Flying Horse Inn (Ipswich) | C11: IP1 5NW | D11: 30ltr Kopparberg Strawb & Lime 4.0 11G/50L San Miguel Grundy 5.0 | E11: 90.3 | H11: Sarah (gareth tender) | I11: SM Top vol and kop top 2. has tnt. Low ops, mostly gk
A12: GK IFT | B12: Falgate Arms (Hiegham) | C12: NR29 5HZ | D12: 10gl Stella Artois 4.6 11G/50L San Miguel Grundy 5.0 | E12: 90.1592 | J12: never visited
A13: GK IFT | B13: Edinburgh Inn (Wells Next to the | C13: NR23 1AE | D13: 10gl Stella Artois 4.6 | E13: 91.8264 | H13: Michael? (jack tender) | I13: 'cheapest pub in cromer'
A14: GK IFT | B14: Eaton Cottage (Norwich) | C14: NR2 2DQ | D14: 10gl Stella Artois 4.6 11G/50L San Miguel Grundy 5.0 | E14: 103.1262 | H14: Phil | I14: mostly gk, small pub, maybe kop opps, nice guy but never comes down just phone. (asked for parasols at one point, told sdm only if he actually meets me and ops)
A15: GK IFT | B15: Crossways Inn Scole Ltd (Scole) | C15: IP21 4DP | D15: 10gl Stella Artois 4.6 11G/50L Becks Vier 4.0 | E15: 91.1874 | H15: Scott | I15: massive place, gorgeous garden, on gk list but with no bbg and becks is pouring- lacons, cmbc, gk - Hells ipo cruz ops | J15: op
A16: GK IFT | B16: Cliff Quay Brewery (Debenham) | C16: IP14 6RP | D16: 10gl Stella Artois 4.6 11G/50L San Miguel Grundy 5.0 | E16: 112.4046 | J16: never visited
A17: GK IFT | B17: Brewer Arms (Brightlingsea) | C17: CO7 0BX | D17: 10gl Stella Artois 4.6 11G/50L San Miguel Grundy 5.0 | E17: 116.0142 | H17: julie ll and maddie tender | I17: tnt ops- is price why they don't have and will share with julie the 50% | J17: tnt
A18: GK IFT | B18: Gorleston Golf Club (Gorleston) | C18: NR31 6JT | D18: 11G/50L Budweiser Draught 4.5 11G/50L San Miguel Grundy 5.0 | E18: 87.5 | J18: never visited
A19: GK IFT | B19: Fishing Boat (East Runton) | C19: NR27 9NX | D19: 10gl Stella Artois 4.6 11G/50L San Miguel Grundy 5.0 | E19: 85.5996 | H19: Sue
A20: GK IFT | B20: Epic Studios (Norwich) | C20: NR3 1JD | D20: 10gl Stella Artois 4.6 | E20: 84.289 | I20: late opening, emailed late 2024 for meet, responded but never responded to book.
A21: GK IFT | B21: Darbys (Swanton) | C21: NR20 4NY | D21: 10gl Stella Artois 4.6 11G/50L Camden Hells Lager 4.6 | E21: 82.9322 | H21: Collin | I21: listing fee running out.
A22: Greene King L&T | B22: Crown | C22: CO10 0AT | D22: San Miguel Stella Artois | E22: 45.828914 | F22: 0.93912511 | I22: San miguel new? Not visited since may 2024
A23: Admiral | B23: Lion | C23: CO10 8HP | D23: Stella Artois | E23: 46.337347 | F23: 1.8101429 | H23: Carmen & Sarah? 07951066228 (Facebook) | I23: never visited
A24: Admiral | B24: Trafalgar | C24: CO12 4LW | D24: San Miguel Stella Artois | E24: 121 | F24: 0.30754338 | H24: Joanne ? 07949839114 (facebook) | I24: Never visited
A25: Admiral | B25: Queens Head Hotel | C25: CO14 8AD | D25: San Miguel Stella Artois | E25: 110 | F25: 0.85365135 | H25: Jane
A26: Greene King L&T | B26: Victory | C26: CO14 8AR | D26: Stella Artois | E26: 32 | F26: Infinity | H26: Emma | I26: San Miguel op with time
A27: Stonegate | B27: Three Jays | C27: CO15 2PJ | D27: Stella Artois Corona Extra | E27: 32 | F27: Infinity | H27: Adrian | I27: Corona on for TNT, joined stella. Rona not doing great, awesome dude, lots of talking. Likely swap rona for sm early 2026. hates huk reps. Plenty of lines
A28: Admiral | B28: Silver Oyster | C28: CO2 8LY | D28: San Miguel | E28: 122.93591 | F28: 0.48301764 | G28: Yes Gallo IFT -The Grapes down the road | H28: Pet & Ami | I28: Next to no ops at Grapes, very low Pale ops ipo neckoil. Listing Fee not enough $$ for increase kegs
A29: Admiral | B29: Brewers Arms | C29: IP1 3NS | D29: Camden Pale Ale Stella Artois | E29: 92 | F29: -0.16233403 | G29: yes Walnute IP14 | H29: Andy (steve partner) | I29: Brands safe, low ops, less SM/Mahou $ against madri
A30: Trust | B30: Royal Oak | C30: IP13 8DH | D30: Becks | E30: 38 | F30: 11.667 | H30: Leanne & Bob est Dec 2024? Facebook | I30: never visited
A31: Greene King L&T | B31: Crown Hotel | C31: IP13 9AP | D31: San Miguel Camden Hells | E31: 37 | F31: 4.095 | H31: Chris | I31: Kopp opps with time. Hells on forever, lost to GK, returned last year ipo aspall
A32: Greene King L&T | B32: Station Hotel | C32: IP2 8AJ | D32: San Miguel Kopparberg Straw & Lime Camden Hells | E32: 99.507756 | F32: Infinity | H32: James | I32: low ops, maybe pale/stella. Huge soccer volume, invested with tables. Class dude, support
A33: Stonegate | B33: Wortwell Bell | C33: IP20 0HH | D33: Becks Stella Artois Camden Hells Kopparberg Straw & Lime | E33: 41.629259 | F33: 0.60605263 | G33: yes | H33: Keighly | I33: awesome lady, goodluck booking in. x3 sites (x2 SG, x1 Lacons - all bbg). Support. Interest in tnt but no movement. Removed sky $$
A34: Admiral | B34: Albion | C34: IP24 2DN | D34: San Miguel Stella Artois | E34: 116 | F34: 0.74868442 | H34: Shawn (lawrence mngr) | I34: Lost Stella.
A35: Admiral | B35: Margaret Catchpole Inn | C35: IP3 0PQ | D35: Stella Artois | E35: 42.691077 | F35: -0.060195094 | H35: Shona | I35: Stella safe on churn, but hurting on business - loves stella but $ fears. Up for pale/kop but $
A36: Punch | B36: Golden Hind | C36: IP3 9NF | D36: San Miguel | E36: 54.808362 | F36: 15.606571 | H36: Ryan | I36: lost stout to murphy-sales nil ops, less hells returns
A37: Greene King L&T | B37: Fox | C37: IP30 9HD | D37: Stella Artois Becks | E37: 55.869672 | F37: -0.15061872 | H37: Jimmy | I37: unlikely ops. Embarrasing ift/lt tnt and listing fee situ? Still support, decent vol, was open to SM with $$ and tnt
A38: Admiral | B38: Gardeners Arms | C38: IP30 9PA | D38: San Miguel Camden Hells | E38: 73.963115 | F38: 0.48051786 | H38: Martin & Claire | I38: new ll, friends with Roly at Chestnut. Gave donation of Belfry tix. Pale pushing but $
A39: Admiral | B39: Dun Cow | C39: IP31 1AA | D39: Stella Artois San Miguel | E39: 33 | F39: 1.753 | H39: Kev | I39: ift ops light. Cider maybe? San miguel issues
A40: Greene King L&T | B40: Woolpack | C40: IP31 1SW | D40: San Miguel | E40: 36 | F40: Infinity | H40: Graham | I40: I good complainer about GK and $. SM safe. Knows the old kop owner? Kop ops,. Hells could be an option ipo gamma (but 'everything is good' and $) also has an IFT site in town, never open
...

Sheet Q1 Churn
A1: Outlet Name | B1: Outlet Postcode | C1: Estate Type | D1: Strike | E1: Distribution in Strike | F1: Brand(s) | G1: Volume YTD | H1: Notes
A2: Angel Sudbury | B2: CO10 2AG | C2: L&T | D2: 1 | E2: 1 | F2: Camden Pale | G2: 2.5003455
A3: Barley Mow Inn | B3: IP6 9EH | C3: L&T | D3: 1 | E3: 1 | F3: Camden Pale | G3: 24.383465
A4: Belle Aire | B4: NR29 4HS | C4: Free Trade | D4: 1 | E4: 1 | F4: San Miguel | G4: 25.280109
A5: Birch Grove Golf Course | B5: CO2 0HS | C5: Free Trade | D5: 1 | E5: 2 | F5: San Miguel Stella Artois | G5: 19.748382
A6: Black Swan | B6: NR10 3HJ | C6: Free Trade | D6: 1 | E6: 2 | F6: Stella Artois San Miguel | G6: 15.779486
A7: Claydon & Barham Social Club & Com | B7: IP6 0EG | C7: Free Trade | D7: 1 | E7: 1 | F7: San Miguel | G7: 7.0146919
A8: Colne Valley Golf Club | B8: CO6 2LT | C8: Free Trade | D8: 1 | E8: 1 | F8: San Miguel | G8: 14.502317
A9: Comfortable Cow | B9: CO10 2EB | C9: Free Trade | D9: 1 | E9: 1 | F9: Stella Artois | G9: 21.422186
A10: Curve Bar | B10: IP1 1RJ | C10: Free Trade | D10: 1 | E10: 1 | F10: San Miguel | G10: 29.004006
A11: Donkey And Buskins | B11: CO2 0HU | C11: Free Trade | D11: 1 | E11: 1 | F11: San Miguel | G11: 29.991626
A12: Duke Of York | B12: IP4 2QP | C12: Free Trade | D12: 1 | E12: 2 | F12: Camden Pale San Miguel | G12: 49.509713
A13: East Coast Bars | B13: NR9 4LF | C13: Free Trade | D13: 1 | E13: 1 | F13: Camden Hells | G13: 41.906698
... A40: Thatch Restaurant (Lowestoft) | B40: NR33 0BY | C40: Free Trade | D40: 1 | E40: 1 | F40: San Miguel | G40: 5.4983249
A41: The Cricketers | B41: NR11 7AA | C41: Free Trade | D41: 1 | E41: 1 | F41: Stella Artois Unfiltered | G41: 66.199195 | H41: not gk - wam?
A42: The Lady Elizabeth | B42: CO10 2EA | C42: L&T | D42: 1 | E42: 1 | F42: San Miguel | G42: 14.502327
A43: Thetford Rugby Club | B43: IP24 1NB | C43: Free Trade | D43: 1 | E43: 1 | F43: Stella Artois | G43: 3.6385396
A44: Three Bottles Inn | B44: CO9 4HY | C44: L&T | D44: 1 | E44: 1 | F44: Camden Hells | G44: 84.826687
A45: Three Tuns | B45: IP6 8AA | C45: Free Trade | D45: 1 | E45: 1 | F45: San Miguel | G45: 52.305402
A46: Twisters | B46: CO1 1PY | C46: Free Trade | D46: 1 | E46: 1 | F46: Camden Hells | G46: 4.5073467
A47: Village Maid | B47: CO11 2UU | C47: Free Trade | D47: 1 | E47: 1 | F47: Stella Artois | G47: 28.650024
A48: Vulcan Arms | B48: IP16 4UD | C48: Free Trade | D48: 1 | E48: 1 | F48: San Miguel | G48: 3.5073459
A49: White Horse | B49: NR14 8ST | C49: L&T | D49: 1 | E49: 1 | F49: San Miguel | G49: 8.4558369
A50: Windmill | B50: NR3 2RE | C50: Free Trade | D50: 1 | E50: 1 | F50: San Miguel | G50: 23.880766
A51: Blue Boar Inn | B51: IP31 3AA | C51: Free Trade | D51: 2 | E51: 1 | F51: San Miguel | G51: 38.406907
A52: Broad Farm Caravan Site | B52: NR29 3AT | C52: Free Trade | D52: 2 | E52: 2 | F52: Budlight San Miguel | G52: 28.502081
A53: Chilton Fields Sports Club | B53: IP14 1LB | C53: Free Trade | D53: 2 | E53: 1 | F53: San Miguel | G53: 29.327716
... A70: Wolf Inn Lowestoft | B70: NR32 3LN | C70: Free Trade | D70: 2 | E70: 1 | F70: Stella Artois | G70: 6.8134216

Sheet Modelo & Eazy Target List
A1: rtm | B1: outlet_name | C1: street_address | D1: town | E1: postcode_outward | F1: postcode_inward | G1: Modelo or Eazy (ros 50l a wk, most $ tap?) | H1: notes
A2: Stonegate | B2: Ferry Inn & Cafe | C2: The Ferry | D2: Felixstowe | E2: IP11 | F2: 9RZ | G2: MODELO | H2: sm delist. swapped for peroni. harry seems gone as tender didn't recognise him amd said call land line gorge location off ocean and golf course.
A3: Stonegate | B3: Gibraltor Gardens | E3: NR2 | F3: 4LZ | G3: MODELO | H3: pending owed investment, likely no until then - but great location
A4: Stonegate | B4: Belle Vue | E4: NR4 | F4: 7AB | G4: MODELO | H4: BOOK MEET
A5: Stonegate | B5: Cottage | E5: NR7 | F5: 0JD | G5: MODELO | H5: possible, book
